INFO     conftest:conftest.py:65 Setting up for test: test_creat_user_invalid_pass_negative
DEBUG    urllib3.connectionpool:connectionpool.py:1049 Starting new HTTPS connection (1): demoqa.com:443
DEBUG    urllib3.connectionpool:connectionpool.py:544 https://demoqa.com:443 "POST /Account/v1/User HTTP/1.1" 201 88
DEBUG    urllib3.connectionpool:connectionpool.py:1049 Starting new HTTPS connection (1): demoqa.com:443
DEBUG    urllib3.connectionpool:connectionpool.py:544 https://demoqa.com:443 "POST /Account/v1/GenerateToken HTTP/1.1" 200 286
DEBUG    urllib3.connectionpool:connectionpool.py:1049 Starting new HTTPS connection (1): demoqa.com:443
DEBUG    urllib3.connectionpool:connectionpool.py:544 https://demoqa.com:443 "POST /Account/v1/Authorized HTTP/1.1" 200 4
DEBUG    urllib3.connectionpool:connectionpool.py:1049 Starting new HTTPS connection (1): demoqa.com:443
DEBUG    urllib3.connectionpool:connectionpool.py:544 https://demoqa.com:443 "POST /Account/v1/User HTTP/1.1" 400 230
INFO     conftest:conftest.py:69 Tearing down after test: test_creat_user_invalid_pass_negative